
public class ExceptionSample1 {
	public static void main(String[] args) {
		int[] num;
		num = new int[3];
		num[3] = 10;
		System.out.println("num[3]に10を代入しました");
		
		System.out.println("正常終了");
	}
}

